Workbook

Sheet Sheet1
A1: APN | B1: CommercialFloorArea_SqFt | C1: YEAR | D1: Notes | E1: WITHIN_TRPA_BNDY
A2: 026-221-53 | B2: 6956 | C2: 2012 | E2: 1
A3: 023-201-75 | B3: 73441 | C3: 2012 | E3: 1
A4: 027-071-31 | B4: 19941 | C4: 2012 | E4: 1
A5: 027-151-34 | B5: 2071 | C5: 2012 | E5: 1
A6: 028-081-08 | B6: 2843 | C6: 2012 | E6: 1
A7: 026-089-10 | B7: 19016 | C7: 2012 | E7: 1
A8: 026-089-09 | B8: 8754 | C8: 2012 | E8: 1
A9: 026-075-19 | B9: 4518 | C9: 2012 | E9: 1
A10: 026-088-22 | B10: 1795 | C10: 2012 | E10: 1
A11: 026-078-17 | B11: 14219 | C11: 2012 | E11: 1
A12: 026-113-14 | B12: 12582 | C12: 2012 | E12: 1
A13: 027-344-47 | B13: 506 | C13: 2012 | E13: 1
... A335: 1318-24-401-008 | B335: 7513 | C335: 2012 | E335: 1
A336: 1319-19-802-004 | B336: 3175 | C336: 2012 | D336: Outside Boundard - Zero Out | E336: 0
A337: 1318-23-401-019 | B337: 759 | C337: 2012 | E337: 1
A338: 1319-19-802-005 | B338: 7110 | C338: 2012 | D338: Outside Boundard - Zero Out | E338: 0
A339: 1318-23-401-013 | B339: 8543 | C339: 2012 | E339: 1
A340: 1318-23-401-028 | B340: 4843 | C340: 2012 | E340: 1
A341: 1318-23-401-027 | B341: 4576 | C341: 2012 | E341: 1
A342: 1318-22-002-010 | B342: 9390 | C342: 2012 | E342: 1
A343: 1318-23-401-037 | B343: 51369 | C343: 2012 | E343: 1
A344: 1318-23-410-001 | B344: 2144 | C344: 2012 | E344: 1
A345: 1318-23-410-076 | B345: 2045 | C345: 2012 | E345: 1
A346: 1318-23-401-022 | B346: 1536 | C346: 2012 | E346: 1
A347: 1318-22-002-012 | B347: 4938 | C347: 2012 | E347: 1
A348: 1318-23-401-009 | B348: 8559 | C348: 2012 | E348: 1
A349: 1318-23-411-001 | B349: 3754 | C349: 2012 | E349: 1
A350: 1318-23-401-030 | B350: 4093 | C350: 2012 | E350: 1
... A1810: 1318-24-601-007 | B1810: 6515 | C1810: 2019 | E1810: 1
A1811: 1319-19-802-005 | B1811: 7110 | C1811: 2019 | D1811: Outside Boundard - Zero Out | E1811: 0
A1812: 1318-26-101-002 | B1812: 3666 | C1812: 2019 | E1812: 1
A1813: 1318-26-101-005 | B1813: 13084 | C1813: 2019 | E1813: 1
A1814: 1318-15-801-002 | B1814: 3477 | C1814: 2019 | E1814: 1
A1815: 1318-22-002-013 | B1815: 3290 | C1815: 2019 | E1815: 1
A1816: 1318-15-803-008 | B1816: 1994 | C1816: 2019 | E1816: 1
A1817: 1318-15-703-002 | B1817: 2987 | C1817: 2019 | E1817: 1
A1818: 1318-15-802-005 | B1818: 2624 | C1818: 2019 | E1818: 1
A1819: 1318-15-802-007 | B1819: 6466 | C1819: 2019 | E1819: 1
A1820: 1318-09-811-018 | B1820: 3396 | C1820: 2019 | E1820: 1
...

Sheet Sheet2
A1: Sum of CommercialFloorArea_SqFt | B1: Column Labels
A2: Row Labels | B2: 2012 | C2: 2018 | D2: 2019 | E2: 2020 | F2: 2021 | G2: 2022 | H2: 2023 | I2: 2024 | J2: Grand Total
A3: 015-331-004 | C3: 1886 | D3: 1886 | E3: 1886 | F3: 1886 | G3: 1886 | H3: 1886 | I3: 1886 | J3: 13202
A4: 015-331-010 | C4: 5862 | D4: 5862 | E4: 5862 | F4: 5862 | G4: 5862 | H4: 5862 | I4: 5862 | J4: 41034
A5: 015-331-028 | C5: 1856 | D5: 1856 | E5: 1856 | F5: 1856 | G5: 1856 | H5: 1856 | I5: 1856 | J5: 12992
A6: 015-331-04 | B6: 1886 | J6: 1886
A7: 015-331-10 | B7: 5862 | J7: 5862
A8: 015-331-28 | B8: 1856 | J8: 1856
A9: 016-292-034 | C9: 124 | D9: 124 | E9: 124 | J9: 372
A10: 016-292-34 | B10: 124 | J10: 124
A11: 016-410-011 | C11: 544 | D11: 544 | E11: 544 | F11: 544 | G11: 544 | H11: 544 | I11: 544 | J11: 3808
A12: 016-410-012 | C12: 8592 | D12: 8592 | E12: 8592 | F12: 8592 | G12: 8592 | H12: 8592 | I12: 8592 | J12: 60144
A13: 016-410-10 | B13: 8592 | J13: 8592
A14: 016-410-11 | B14: 544 | J14: 544
A15: 018-320-018 | C15: 1163 | D15: 1163 | E15: 1163 | F15: 1163 | G15: 1163 | H15: 1163 | I15: 1163 | J15: 8141
A16: 018-320-12 | B16: 1163 | J16: 1163
A17: 022-210-030 | C17: 25780 | D17: 25780 | E17: 25780 | F17: 25780 | G17: 25780 | H17: 25780 | I17: 25780 | J17: 180460
A18: 022-210-30 | B18: 25780 | J18: 25780
A19: 023-111-032 | C19: 4476 | D19: 4476 | E19: 4476 | F19: 4476 | G19: 4476 | H19: 4476 | I19: 4476 | J19: 31332
A20: 023-111-036 | C20: 1812 | D20: 1812 | E20: 1812 | F20: 1812 | G20: 1812 | H20: 1812 | I20: 1812 | J20: 12684
A21: 023-111-037 | C21: 6354 | D21: 6354 | E21: 6354 | F21: 6354 | G21: 6354 | H21: 6354 | I21: 6354 | J21: 44478
A22: 023-111-32 | B22: 4476 | J22: 4476
A23: 023-111-36 | B23: 1812 | J23: 1812
A24: 023-111-37 | B24: 6354 | J24: 6354
A25: 023-132-021 | C25: 820 | D25: 820 | E25: 820 | F25: 820 | G25: 820 | H25: 820 | I25: 820 | J25: 5740
A26: 023-132-21 | B26: 820 | J26: 820
A27: 023-151-009 | C27: 1220 | D27: 1220 | E27: 1220 | F27: 1220 | G27: 1220 | H27: 1220 | I27: 1220 | J27: 8540
A28: 023-151-09 | B28: 1220 | J28: 1220
A29: 023-161-017 | C29: 8454 | D29: 8454 | E29: 8454 | F29: 8454 | G29: 8454 | H29: 8454 | I29: 8454 | J29: 59178
A30: 023-161-033 | C30: 5787 | F30: 5787 | J30: 11574
A31: 023-161-034 | C31: 3230 | D31: 3230 | E31: 3230 | F31: 3230 | G31: 3230 | H31: 3230 | I31: 3230 | J31: 22610
A32: 023-161-17 | B32: 8454 | J32: 8454
A33: 023-161-34 | B33: 3230 | J33: 3230
A34: 023-171-010 | C34: 734 | D34: 734 | E34: 734 | F34: 734 | G34: 734 | H34: 734 | I34: 734 | J34: 5138
A35: 023-171-011 | C35: 3425 | D35: 3425 | E35: 3425 | F35: 3425 | G35: 3425 | H35: 3425 | I35: 3425 | J35: 23975
A36: 023-171-018 | C36: 3608 | D36: 3608 | E36: 3608 | F36: 3608 | G36: 3608 | H36: 3608 | I36: 3608 | J36: 25256
A37: 023-171-023 | C37: 12784 | D37: 12784 | E37: 12784 | F37: 12784 | G37: 12784 | H37: 12784 | I37: 12784 | J37: 89488
A38: 023-171-024 | C38: 7075 | D38: 7075 | E38: 7075 | F38: 7075 | G38: 7075 | H38: 7075 | I38: 7075 | J38: 49525
A39: 023-171-10 | B39: 734 | J39: 734
A40: 023-171-11 | B40: 3425 | J40: 3425
...

Sheet Details
A1: Row Labels | B1: Jurisdiction | C1: CY2012 | D1: CY2013 | E1: CY2014 | F1: CY2015 | G1: CY2016 | H1: CY2017 | I1: CY2018 | J1: CY2019 | K1: CY2020 | L1: CY2021 | M1: CY2022 | N1: CY2023 | O1: CY2024 | P1: CY2025
A2: 015-331-04 | B2: EL | C2: 1886 | D2: 1886 | E2: 1886 | F2: 1886 | G2: 1886 | H2: 1886
A3: 015-331-004 | B3: EL | I3: 1886 | J3: 1886 | K3: 1886 | L3: 1886 | M3: 1886 | N3: 1886 | O3: 1886 | P3: 1886
A4: 015-331-10 | B4: EL | C4: 5862 | D4: 5862 | E4: 5862 | F4: 5862 | G4: 5862 | H4: 5862
A5: 015-331-010 | B5: EL | I5: 5862 | J5: 5862 | K5: 5862 | L5: 5862 | M5: 5862 | N5: 5862 | O5: 5862 | P5: 5862
A6: 015-331-28 | B6: EL | C6: 1856 | D6: 1856 | E6: 1856 | F6: 1856 | G6: 1856 | H6: 1856
A7: 015-331-028 | B7: EL | I7: 1856 | J7: 1856 | K7: 1856 | L7: 1856 | M7: 1856 | N7: 1856 | O7: 1856 | P7: 1856
A8: 016-292-34 | B8: EL | C8: 316 | D8: 316 | E8: 316 | F8: 316 | G8: 316 | H8: 316
A9: 016-292-034 | B9: EL | I9: 316 | J9: 316 | K9: 316
A10: 016-410-11 | B10: EL | C10: 544 | D10: 544 | E10: 544 | F10: 544 | G10: 544 | H10: 544
A11: 016-410-011 | B11: EL | I11: 544 | J11: 544 | K11: 544 | L11: 544 | M11: 544 | N11: 544 | O11: 544 | P11: 544
A12: 016-410-10 | B12: EL | C12: 8592 | D12: 8592 | E12: 8592 | F12: 8592 | G12: 8592 | H12: 8592
A13: 016-410-012 | B13: EL | I13: 8592 | J13: 8592 | K13: 8592 | L13: 8592 | M13: 8592 | N13: 8592 | O13: 8592 | P13: 8592
A14: 018-320-12 | B14: EL | C14: 1163 | E14: 1163 | F14: 1163 | G14: 1163 | H14: 1163
A15: 018-320-11 | B15: EL | D15: 1163
A16: 018-320-018 | B16: EL | I16: 1163 | J16: 1163 | K16: 1163 | L16: 1163 | M16: 1163 | N16: 1163 | O16: 1163 | P16: 1163
A17: 022-210-30 | B17: CSLT | C17: 25780 | D17: 25780 | E17: 25780 | F17: 25780 | G17: 25780 | H17: 25780
A18: 022-210-030 | B18: CSLT | I18: 25780 | J18: 25780 | K18: 25780 | L18: 25780 | M18: 25780 | N18: 25780 | O18: 25780 | P18: 25780
A19: 022-210-32 | B19: CSLT | C19: 49809 | D19: 49809 | E19: 49809 | F19: 49809 | G19: 49809 | H19: 49809
A20: 022-210-032 | B20: CSLT | I20: 49809 | J20: 49809 | K20: 49809 | L20: 49809 | M20: 49809 | N20: 49809 | O20: 49809 | P20: 49809
A21: 023-111-32 | B21: CSLT | C21: 4476 | D21: 4476 | E21: 4476 | F21: 4476 | G21: 4476 | H21: 4476
A22: 023-111-032 | B22: CSLT | I22: 4476 | J22: 4476 | K22: 4476 | L22: 4476 | M22: 4476 | N22: 4476 | O22: 4476 | P22: 4476
A23: 023-111-36 | B23: CSLT | C23: 1812 | D23: 1812 | E23: 1812 | F23: 1812 | G23: 1812 | H23: 1812
A24: 023-111-036 | B24: CSLT | I24: 1812 | J24: 1812 | K24: 1812 | L24: 1812 | M24: 1812 | N24: 1812 | O24: 1812 | P24: 1812
A25: 023-111-37 | B25: CSLT | C25: 6354 | D25: 6354 | E25: 6354 | F25: 6354 | G25: 6354 | H25: 6354
A26: 023-111-037 | B26: CSLT | I26: 6354 | J26: 6354 | K26: 6354 | L26: 6354 | M26: 6354 | N26: 6354 | O26: 6354 | P26: 6354
A27: 023-132-21 | B27: CSLT | C27: 820 | D27: 820 | E27: 820 | F27: 820 | G27: 820 | H27: 820
A28: 023-132-021 | B28: CSLT | I28: 820 | J28: 820 | K28: 820 | L28: 820 | M28: 820 | N28: 820 | O28: 820 | P28: 820
A29: 023-151-09 | B29: CSLT | C29: 1220 | D29: 1220 | E29: 1220 | F29: 1220 | G29: 1220 | H29: 1220
A30: 023-151-009 | B30: CSLT | I30: 1220 | J30: 1220 | K30: 1220 | L30: 1220 | M30: 1220 | N30: 1220 | O30: 1220 | P30: 1220
A31: 023-161-17 | B31: CSLT | C31: 8454 | D31: 8454 | E31: 8454 | F31: 8454 | G31: 8454 | H31: 8454
A32: 023-161-017 | B32: CSLT | I32: 8454 | J32: 8454 | K32: 8454 | L32: 8454 | M32: 8454 | N32: 8454 | O32: 8454 | P32: 8454
A33: 023-161-33 | B33: CSLT | C33: 5787 | D33: 5787 | E33: 5787 | F33: 5787 | G33: 5787 | H33: 5787
A34: 023-161-033 | B34: CSLT | I34: 5787 | J34: 5787 | K34: 5787 | L34: 5787 | M34: 5787 | N34: 5787 | O34: 5787 | P34: 5787
A35: 023-161-34 | B35: CSLT | C35: 3230 | D35: 3230 | E35: 3230 | F35: 3230 | G35: 3230 | H35: 3230
A36: 023-161-034 | B36: CSLT | I36: 3230 | J36: 3230 | K36: 3230 | L36: 3230 | M36: 3230 | N36: 3230 | O36: 3230 | P36: 3230
A37: 023-171-10 | B37: CSLT | C37: 734 | D37: 734 | E37: 734 | F37: 734 | G37: 734 | H37: 734
A38: 023-171-010 | B38: CSLT | I38: 734 | J38: 734 | K38: 734 | L38: 734 | M38: 734 | N38: 734 | O38: 734 | P38: 734
A39: 023-171-11 | B39: CSLT | C39: 3425 | D39: 3425 | E39: 3425 | F39: 3425 | G39: 3425 | H39: 3425
A40: 023-171-011 | B40: CSLT | I40: 3425 | J40: 3425 | K40: 3425 | L40: 3425 | M40: 3425 | N40: 3425 | O40: 3425 | P40: 3425
...

Sheet Summary
A1: CFA Accounting
B4: 2012 | C4: 2013 | D4: 2014 | E4: 2015 | F4: 2016 | G4: 2017 | H4: 2018 | I4: 2019 | J4: 2020 | K4: 2021 | L4: 2022 | M4: 2023 | N4: 2024 | O4: 2025 | S4: NET CHANGE FROM 2012
A5: Existing | B5: =SUM(Details!C:C) -> 6581919 | C5: =SUM(Details!D:D) -> 6587387 | D5: =SUM(Details!E:E) -> 6609450 | E5: =SUM(Details!F:F) -> 6598123 | F5: =SUM(Details!G:G) -> 6601783 | G5: =SUM(Details!H:H) -> 6573092 | H5: =SUM(Details!I:I) -> 6617617 | I5: =SUM(Details!J:J) -> 6622199 | J5: =SUM(Details!K:K) -> 6607012 | K5: =SUM(Details!L:L) -> 6609588 | L5: =SUM(Details!M:M) -> 6610535 | M5: =SUM(Details!N:N) -> 6609970 | N5: =SUM(Details!O:O) -> 6592958 | O5: =SUM(Details!P:P) -> 6583769 | S5: =O5-B5 -> 1850
A6: Change | B6: n/a | C6: =C5-B5 -> 5468 | D6: =D5-C5 -> 22063 | E6: =E5-D5 -> -11327 | F6: =F5-E5 -> 3660 | G6: =G5-F5 -> -28691 | H6: =H5-G5 -> 44525 | I6: =I5-H5 -> 4582 | J6: =J5-I5 -> -15187 | ... O6: =O5-N5 -> -9189 | S6: =S5/B5 -> 0.00028107304
C7: =C5/B5-1 -> 0.00083076076 | D7: =D5/C5-1 -> 0.0033492795 | E7: =E5/D5-1 -> -0.0017137583 | F7: =F5/E5-1 -> 0.00055470321 | G7: =G5/F5-1 -> -0.0043459471 | H7: =H5/G5-1 -> 0.0067738288 | I7: =I5/H5-1 -> 0.00069239426 | J7: =J5/I5-1 -> -0.002293347 | ... O7: =O5/N5-1 -> -0.0013937598
A10: Net Change | B10: n/a | C10: =C13+C21 -> 5468 | D10: =D13+D21 -> 22063 | E10: =E13+E21 -> -11327 | F10: =F13+F21 -> 3660 | G10: =G13+G21 -> -28691 | H10: =H13+H21 -> 44525 | I10: =I13+I21 -> 4582 | J10: =J13+J21 -> -15187 | ... O10: =O13+O21 -> -9189 | S10: =SUM(C10:O10) -> 1850
C11: =C10=C6 -> TRUE | D11: =D10=D6 -> TRUE | E11: =E10=E6 -> TRUE | F11: =F10=F6 -> TRUE | G11: =G10=G6 -> TRUE | H11: =H10=H6 -> TRUE | I11: =I10=I6 -> TRUE | J11: =J10=J6 -> TRUE | ... O11: =O10=O6 -> TRUE
A13: Added | B13: n/a | C13: =SUM(C14:C17) -> 7220 | D13: =SUM(D14:D17) -> 24639 | E13: =SUM(E14:E17) -> 10193 | F13: =SUM(F14:F17) -> 10819 | G13: =SUM(G14:G17) -> 34791 | H13: =SUM(H14:H17) -> 48463 | I13: =SUM(I14:I17) -> 8359 | J13: =SUM(J14:J17) -> 2171 | ... O13: =SUM(O14:O17) -> 1959 | S13: =SUM(C13:O13) -> 184554
A14: Added from Allocations | B14: n/a | C14: 6973 | D14: 18139 | E14: 5122 | F14: 4698 | G14: 28849 | H14: 24726 | I14: 6759 | J14: 936 | K14: 0 | L14: 6635 | M14: 2977 | N14: 0 | O14: 1959 | S14: =SUM(C14:O14) -> 107773
A15: Added from Transfer | B15: n/a | C15: 247 | D15: 6500 | E15: 3532 | F15: 0 | G15: 5942 | H15: 0 | I15: 0 | J15: 0 | K15: 1686 | L15: 650 | M15: 2996 | N15: 9700 | O15: 0 | S15: =SUM(C15:O15) -> 31253
A16: Added from Conversions | B16: n/a | C16: 0 | D16: 0 | E16: 0 | F16: 0 | G16: 0 | H16: 0 | I16: 0 | J16: 0 | K16: 8564 | L16: 0 | M16: 0 | N16: 0 | O16: 0 | S16: =SUM(C16:O16) -> 8564
A17: Added from Banked | B17: n/a | C17: 0 | D17: 0 | E17: 1539 | F17: 6121 | G17: 0 | H17: 23737 | I17: 1600 | J17: 1235 | K17: 0 | L17: 246 | M17: 0 | N17: 2486 | O17: 0 | S17: =SUM(C17:O17) -> 36964
A21: Removed | B21: n/a | C21: =SUM(C22:C23) -> -1752 | D21: =SUM(D22:D23) -> -2576 | E21: =SUM(E22:E23) -> -21520 | F21: =SUM(F22:F23) -> -7159 | G21: =SUM(G22:G23) -> -63482 | H21: =SUM(H22:H23) -> -3938 | I21: =SUM(I22:I23) -> -3777 | J21: =SUM(J22:J23) -> -17358 | ... O21: =SUM(O22:O23) -> -11148 | S21: =SUM(C21:O21) -> -182704
A22: Banked | B22: n/a | C22: -1752 | D22: -2576 | E22: -21520 | F22: -7159 | G22: -63482 | H22: -3938 | I22: -3777 | J22: -13358 | K22: -674 | L22: -6284 | M22: -6538 | N22: -29198 | O22: =-1911-3797-576 -> -6284 | S22: =SUM(C22:O22) -> -166540
A23: Converted | B23: n/a | C23: 0 | D23: 0 | E23: 0 | F23: 0 | G23: 0 | H23: 0 | I23: 0 | J23: -4000 | K23: -7000 | L23: -300 | M23: 0 | N23: 0 | O23: -4864 | S23: =SUM(C23:O23) -> -16164
A27: Major Completed Projects | C27: Bob Dogs Pizza Meyers | D27: Chateau at the Village, SLT | E27: Heavenly Village Cinema Loft | G27: U-Haul, SLT | H27: Bijou Marketplace/Whole Foods | I27: Blue Granite Climbing Gym | K27: TAU to Commercial Conversion SLT (Gym Love/Axe Throwing) | L27: Bowl Incline | N27: Natural Grocers Incline | O27: Southside Autobody, SLT
E28: Autozone, SLT
G29: Barton CFA Banking/Conversion to HCD | N29: Lakeside Inn CFA Banking
A36: Jurisdiction | B36: 2012 | C36: 2013 | D36: 2014 | E36: 2015 | F36: 2016 | G36: 2017 | H36: 2018 | I36: 2019 | J36: 2020 | K36: 2021 | L36: 2022 | M36: 2023 | N36: 2024 | O36: 2025
A37: City of South Lake Tahoe | B37: 3011030 | C37: 3014110 | D37: 3032684 | E37: 3037090 | F37: 3036290 | G37: 3007878 | H37: 3054738 | I37: 3063097 | J37: 3061267 | K37: 3065985 | L37: 3063880 | M37: 3060852 | N37: 3060852 | O37: 3050411
A38: Douglas County | B38: 700578 | C38: 698826 | D38: 701556 | E38: 701556 | F38: 701556 | G38: 701556 | H38: 701556 | I38: 701556 | J38: 695991 | K38: 695991 | L38: 695991 | M38: 695991 | N38: 674201 | O38: 674201
A39: El Dorado County | B39: 327909 | C39: 327576 | D39: 330911 | E39: 330911 | F39: 330911 | G39: 330911 | H39: 330911 | I39: 330911 | J39: 330911 | K39: 330595 | L39: 330595 | M39: 330595 | N39: 330595 | O39: 330595
A40: Placer County | B40: 1345080 | C40: 1349553 | D40: 1346977 | E40: 1335115 | F40: 1339813 | G40: 1339813 | H40: 1337478 | I40: 1333701 | J40: 1325909 | K40: 1325909 | L40: 1325909 | M40: 1325376 | N40: 1320454 | O40: 1321706
A41: Washoe County | B41: 1197322 | C41: 1197322 | D41: 1197322 | E41: 1193451 | F41: 1193213 | G41: 1192934 | H41: 1192934 | I41: 1192934 | J41: 1192934 | K41: 1191108 | L41: 1194160 | M41: 1197156 | N41: 1206856 | O41: 1206856
A42: Grand Total | B42: 6581919 | C42: 6587387 | D42: 6609450 | E42: 6598123 | F42: 6601783 | G42: 6573092 | H42: 6617617 | I42: 6622199 | J42: 6607012 | K42: 6609588 | L42: 6610535 | M42: 6609970 | N42: 6592958 | O42: 6583769
B45: =B42=B5 -> TRUE | C45: =C42=C5 -> TRUE | D45: =D42=D5 -> TRUE | E45: =E42=E5 -> TRUE | F45: =F42=F5 -> TRUE | G45: =G42=G5 -> TRUE | H45: =H42=H5 -> TRUE | I45: =I42=I5 -> TRUE | ... O45: =O42=O5 -> TRUE
