Workbook

Sheet TAU details
A1: APN | B1: Jurisdiction | C1: CY2012 | D1: CY2013 | E1: CY2014 | F1: CY2015 | G1: CY2016 | H1: CY2017 | I1: CY2018 | J1: CY2019 | K1: CY2020 | L1: CY2021 | M1: CY2022 | N1: CY2023 | O1: CY2024 | P1: CY2025
A2: 015-331-004 | B2: EL | I2: 7 | J2: 7 | K2: 7 | L2: 7 | M2: 7 | N2: 7 | O2: 7 | P2: 7
A3: 015-331-005 | B3: EL | I3: 12 | J3: 12 | K3: 12 | L3: 12 | M3: 12 | N3: 12 | O3: 12 | P3: 12
A4: 015-331-04 | B4: EL | C4: 7 | D4: 7 | E4: 7 | F4: 7 | G4: 7 | H4: 7
A5: 015-331-05 | B5: EL | C5: 12 | D5: 12 | E5: 12 | F5: 12 | G5: 12 | H5: 12
A6: 016-041-010 | B6: EL | I6: 22 | J6: 22 | K6: 22 | L6: 22 | M6: 22 | N6: 22 | O6: 22 | P6: 22
A7: 016-041-10 | B7: EL | C7: 22 | D7: 22 | E7: 22 | F7: 22 | G7: 22 | H7: 22
A8: 023-111-037 | B8: CSLT | I8: 10 | J8: 10 | K8: 10 | L8: 10 | M8: 10 | N8: 10 | O8: 10 | P8: 10
A9: 023-111-046 | B9: CSLT | I9: 30 | J9: 30 | K9: 30 | L9: 30 | M9: 30 | N9: 30 | O9: 30 | P9: 30
A10: 023-111-37 | B10: CSLT | C10: 10 | D10: 10 | E10: 10 | F10: 10 | G10: 10 | H10: 10
A11: 023-111-46 | B11: CSLT | C11: 30 | D11: 30 | E11: 30 | F11: 30 | G11: 30 | H11: 30
A12: 023-132-004 | B12: CSLT | I12: 11 | J12: 11 | K12: 11 | L12: 11 | M12: 11 | N12: 11 | O12: 11 | P12: 11
A13: 023-132-023 | B13: CSLT | I13: 16 | J13: 16 | K13: 16 | L13: 16 | M13: 16 | N13: 16 | O13: 16 | P13: 16
A14: 023-132-04 | B14: CSLT | C14: 11 | D14: 11 | E14: 11 | F14: 11 | G14: 11 | H14: 11
A15: 023-132-23 | B15: CSLT | C15: 16 | D15: 16 | E15: 16 | F15: 16 | G15: 16 | H15: 16
A16: 023-141-006 | B16: CSLT | I16: 21 | J16: 21 | K16: 21 | L16: 21 | M16: 21 | N16: 21 | O16: 21 | P16: 21
A17: 023-141-06 | B17: CSLT | C17: 21 | D17: 21 | E17: 21 | F17: 21 | G17: 21 | H17: 21
A18: 023-161-005 | B18: CSLT | I18: 21 | J18: 21 | K18: 21 | L18: 21 | M18: 21 | N18: 21 | O18: 21 | P18: 21
A19: 023-161-006 | B19: CSLT | I19: 17 | J19: 17 | K19: 17 | L19: 17 | M19: 17 | N19: 17 | O19: 17 | P19: 17
A20: 023-161-05 | B20: CSLT | C20: 21 | D20: 21 | E20: 21 | F20: 21 | G20: 21 | H20: 21
A21: 023-161-06 | B21: CSLT | C21: 17 | D21: 17 | E21: 17 | F21: 17 | G21: 17 | H21: 17
A22: 023-211-022 | B22: CSLT | I22: 21 | J22: 21 | K22: 21 | L22: 21 | M22: 21 | N22: 21
A23: 023-211-035 | B23: CSLT | I23: 18 | J23: 18 | K23: 18 | L23: 18 | M23: 18 | N23: 18 | O23: 18 | P23: 18
A24: 023-211-041 | B24: CSLT | I24: 18 | J24: 18 | K24: 18 | L24: 18 | M24: 18 | N24: 18 | O24: 18 | P24: 18
A25: 023-211-22 | B25: CSLT | C25: 21 | D25: 21 | E25: 21 | F25: 21 | G25: 21 | H25: 21
A26: 023-211-35 | B26: CSLT | C26: 18 | D26: 18 | E26: 18 | F26: 18 | G26: 18 | H26: 18
A27: 023-211-41 | B27: CSLT | C27: 18 | D27: 18 | E27: 18 | F27: 18 | G27: 18 | H27: 18
A28: 023-251-030 | B28: CSLT | I28: 21 | J28: 21 | K28: 21 | L28: 21 | M28: 21 | N28: 21 | O28: 21 | P28: 21
A29: 023-251-30 | B29: CSLT | C29: 21 | D29: 21 | E29: 21 | F29: 21 | G29: 21 | H29: 21
A30: 025-580-007 | B30: CSLT | I30: 8 | J30: 8 | K30: 8 | L30: 8 | M30: 8 | N30: 8 | O30: 8 | P30: 8
A31: 025-580-07 | B31: CSLT | C31: 8 | D31: 8 | E31: 8 | F31: 8 | G31: 8 | H31: 8
A32: 026-043-015 | B32: CSLT | I32: 22 | J32: 22 | K32: 22 | L32: 22 | M32: 22 | N32: 22 | O32: 22 | P32: 22
A33: 026-043-15 | B33: CSLT | C33: 22 | D33: 22 | E33: 22 | F33: 22 | G33: 22 | H33: 22
A34: 026-084-006 | B34: CSLT | I34: 15 | J34: 15 | K34: 15 | L34: 15 | M34: 15 | N34: 15 | O34: 15 | P34: 15
A35: 026-084-06 | B35: CSLT | C35: 15 | D35: 15 | E35: 15 | F35: 15 | G35: 15 | H35: 15
A36: 026-114-026 | B36: CSLT | I36: 26 | J36: 26 | K36: 26 | L36: 26 | M36: 26 | N36: 26 | O36: 26 | P36: 26
A37: 026-114-26 | B37: CSLT | C37: 26 | D37: 26 | E37: 26 | F37: 26 | G37: 26 | H37: 26
A38: 027-020-010 | B38: CSLT | I38: 60 | J38: 60 | K38: 60 | L38: 60 | M38: 60 | N38: 60 | O38: 60 | P38: 60
A39: 027-020-017 | B39: CSLT | I39: 50 | J39: 50 | K39: 50 | L39: 50 | M39: 50 | N39: 50 | O39: 50 | P39: 50
A40: 027-020-10 | B40: CSLT | C40: 60 | D40: 60 | E40: 60 | F40: 60 | G40: 60 | H40: 60
...

Sheet TAU Summary
A1: TAU Accounting
B4: 2012 | C4: 2013 | D4: 2014 | E4: 2015 | F4: 2016 | G4: 2017 | H4: 2018 | I4: 2019 | J4: 2020 | K4: 2021 | L4: 2022 | M4: 2023 | N4: 2024 | O4: 2025 | S4: NET CHANGE FROM 2012
A5: Existing | B5: =SUM('TAU details'!C:C) -> 11180 | C5: =SUM('TAU details'!D:D) -> 11175 | D5: =SUM('TAU details'!E:E) -> 11175 | E5: =SUM('TAU details'!F:F) -> 11153 | F5: =SUM('TAU details'!G:G) -> 11108 | G5: =SUM('TAU details'!H:H) -> 11139 | H5: =SUM('TAU details'!I:I) -> 11156 | I5: =SUM('TAU details'!J:J) -> 11150 | J5: =SUM('TAU details'!K:K) -> 11150 | K5: =SUM('TAU details'!L:L) -> 11094 | L5: =SUM('TAU details'!M:M) -> 11107 | M5: =SUM('TAU details'!N:N) -> 11114 | N5: =SUM('TAU details'!O:O) -> 10969 | O5: =SUM('TAU details'!P:P) -> 10761 | S5: =O5-B5 -> -419
A6: Change | B6: n/a | C6: =C5-B5 -> -5 | D6: =D5-C5 -> 0 | E6: =E5-D5 -> -22 | F6: =F5-E5 -> -45 | G6: =G5-F5 -> 31 | H6: =H5-G5 -> 17 | I6: =I5-H5 -> -6 | J6: =J5-I5 -> 0 | ... O6: =O5-N5 -> -208 | S6: =S5/B5 -> -0.037477639
C7: =C5/B5-1 -> -0.00044722719 | D7: =D5/C5-1 -> 0 | E7: =E5/D5-1 -> -0.0019686801 | F7: =F5/E5-1 -> -0.0040347888 | G7: =G5/F5-1 -> 0.0027907814 | H7: =H5/G5-1 -> 0.0015261693 | I7: =I5/H5-1 -> -0.00053782718 | J7: =J5/I5-1 -> 0 | ... O7: =O5/N5-1 -> -0.018962531
A10: Net Change | B10: n/a | C10: =C13+C21 -> -5 | D10: =D13+D21 -> 0 | E10: =E13+E21 -> -22 | F10: =F13+F21 -> -45 | G10: =G13+G21 -> 31 | H10: =H13+H21 -> 17 | I10: =I13+I21 -> -6 | J10: =J13+J21 -> 0 | ... O10: =O13+O21 -> -208 | S10: =SUM(C10:O10) -> -419
C11: =C10=C6 -> TRUE | D11: =D10=D6 -> TRUE | E11: =E10=E6 -> TRUE | F11: =F10=F6 -> TRUE | G11: =G10=G6 -> TRUE | H11: =H10=H6 -> TRUE | I11: =I10=I6 -> TRUE | J11: =J10=J6 -> TRUE | ... O11: =O10=O6 -> TRUE
A13: Added | B13: n/a | C13: =SUM(C14:C17) -> 0 | D13: =SUM(D14:D17) -> 0 | E13: =SUM(E14:E17) -> 0 | F13: =SUM(F14:F17) -> 0 | G13: =SUM(G14:G17) -> 154 | H13: =SUM(H14:H17) -> 32 | I13: =SUM(I14:I17) -> 5 | J13: =SUM(J14:J17) -> 0 | ... O13: =SUM(O14:O17) -> 0 | S13: =SUM(C13:O13) -> 211
A14: Added from Allocations | B14: n/a | C14: 0 | D14: 0 | E14: 0 | F14: 0 | G14: 0 | H14: 0 | I14: 0 | J14: 0 | K14: 0 | L14: 0 | M14: 0 | N14: 0 | O14: 0 | S14: =SUM(C14:O14) -> 0
A15: Added from Transfer | B15: n/a | C15: 0 | D15: 0 | E15: 0 | F15: 0 | G15: 154 | H15: 32 | I15: 0 | J15: 0 | K15: 0 | L15: 12 | M15: 7 | N15: 0 | O15: 0 | S15: =SUM(C15:O15) -> 205
A16: Added from Conversions | B16: n/a | C16: 0 | D16: 0 | E16: 0 | F16: 0 | G16: 0 | H16: 0 | I16: 0 | J16: 0 | K16: 0 | L16: 1 | M16: 0 | N16: 0 | O16: 0 | S16: =SUM(C16:O16) -> 1
A17: Added from Banked | B17: n/a | C17: 0 | D17: 0 | E17: 0 | F17: 0 | G17: 0 | H17: 0 | I17: 5 | J17: 0 | K17: 0 | L17: 0 | M17: 0 | N17: 0 | O17: 0 | S17: =SUM(C17:O17) -> 5
A21: Removed | B21: n/a | C21: =SUM(C22:C23) -> -5 | D21: =SUM(D22:D23) -> 0 | E21: =SUM(E22:E23) -> -22 | F21: =SUM(F22:F23) -> -45 | G21: =SUM(G22:G23) -> -123 | H21: =SUM(H22:H23) -> -15 | I21: =SUM(I22:I23) -> -11 | J21: =SUM(J22:J23) -> 0 | ... O21: =SUM(O22:O23) -> -208 | S21: =SUM(C21:O21) -> -630
A22: Banked | B22: n/a | C22: -5 | D22: 0 | E22: -22 | F22: -33 | G22: -123 | H22: -15 | I22: -11 | J22: 0 | K22: -23 | L22: 0 | M22: 0 | N22: -124 | O22: =-67-141 -> -208 | S22: =SUM(C22:O22) -> -564
A23: Converted | B23: n/a | C23: 0 | D23: 0 | E23: 0 | F23: -12 | G23: 0 | H23: 0 | I23: 0 | J23: 0 | K23: -33 | L23: 0 | M23: 0 | N23: -21 | O23: 0 | S23: =SUM(C23:O23) -> -66
A27: Major Completed Projects | G27: Edgewood Lodge (154 units) | H27: Zalanta (32 units) | I27: Landing (5 units) | L27: Edgewood Casitas (7 units) | M27: Edgewood Casitas (7 units)
F28: Peak10 Conversion and Banking (27 units) | L28: Desolation Hotel (21 units) | O28: Motel 6 Banking (141 Units)
E29: South Y Lodge Banking (CTC, 9 units) | G29: Knights Inn Banking (110 units) | H29: Calneva Banking (15 units) | N29: Lakeside Inn Banking (124 units) | O29: Sunray Motel Banking (64 units) | R29: Corrections
F30: Calneva Banking (18 units) | G30: Landing Banking (13 units) | K30: TAU to Commercial Conversion SLT (Gym Love/Axe Throwing)
A36: Jurisdiction | B36: 2012 | C36: 2013 | D36: 2014 | E36: 2015 | F36: 2016 | G36: 2017 | H36: 2018 | I36: 2019 | J36: 2020 | K36: 2021 | L36: 2022 | M36: 2023 | N36: 2024 | O36: 2025
A37: City of South Lake Tahoe | B37: 6088 | C37: 6088 | D37: 6088 | E37: 6066 | F37: 6066 | G37: 5943 | H37: 5975 | I37: 5980 | J37: 5980 | K37: 5953 | L37: 5959 | M37: 5959 | N37: 5938 | O37: 5733
A38: Douglas County | B38: 2650 | C38: 2650 | D38: 2650 | E38: 2650 | F38: 2650 | G38: 2804 | H38: 2804 | I38: 2804 | J38: 2804 | K38: 2804 | L38: 2811 | M38: 2818 | N38: 2694 | O38: 2694
A39: El Dorado County | B39: 112 | C39: 112 | D39: 112 | E39: 112 | F39: 112 | G39: 112 | H39: 112 | I39: 112 | J39: 112 | K39: 112 | L39: 112 | M39: 112 | N39: 112 | O39: 112
A40: Placer County | B40: 1295 | C40: 1290 | D40: 1290 | E40: 1290 | F40: 1263 | G40: 1263 | H40: 1263 | I40: 1252 | J40: 1252 | K40: 1223 | L40: 1223 | M40: 1223 | N40: 1223 | O40: 1220
A41: Washoe County | B41: 1035 | C41: 1035 | D41: 1035 | E41: 1035 | F41: 1017 | G41: 1017 | H41: 1002 | I41: 1002 | J41: 1002 | K41: 1002 | L41: 1002 | M41: 1002 | N41: 1002 | O41: 1002
A42: Grand Total | B42: 11180 | C42: 11175 | D42: 11175 | E42: 11153 | F42: 11108 | G42: 11139 | H42: 11156 | I42: 11150 | J42: 11150 | K42: 11094 | L42: 11107 | M42: 11114 | N42: 10969 | O42: 10761
